Workbook

Sheet 1+2

Sheet 3+4
B1: תשלום התאחדות
B2: תחרות בוגרים 3+4 - 2024
B3: שם המקצה | C3: מספר כניסות | D3: קופון ענף | E3: קופון דרבי | F3: תשלום לפרס | G3: התאחדות | H3: סה"כ קופון ענף למקצה | I3: סה"כ תשלום לפרס למקצה | J3: סה"כ ג'קפוט למקצה | K3: סה"כ פרס כספי למקצה | L3: סה"כ הכנסות התאחדות ממקצה
B4: NRHA Non Pro | C4: 13 | D4: =(650-E4)*0.1 -> 60 | E4: 50 | F4: =G4-E4-D4 -> 140 | G4: 250 | H4: =D4*C4 -> 780 | I4: =F4*C4 -> 1820 | J4: 0 | K4: 4000 | L4: =C4*G4 -> 3250
B5: NRHA Limited Non Pro | C5: 15 | D5: =(450-E5)*0.1 -> 40 | E5: 50 | F5: =G5-E5-D5 -> 90 | G5: 180 | H5: =D5*C5 -> 600 | I5: =F5*C5 -> 1350 | J5: 0 | K5: 1200 | L5: =C5*G5 -> 2700
B6: NRHA Limited Open | C6: 8 | D6: =(500-E6)*0.1 -> 45 | E6: 50 | F6: =G6-E6-D6 -> 105 | G6: 200 | H6: =D6*C6 -> 360 | I6: =F6*C6 -> 840 | J6: 0 | K6: 2000 | L6: =C6*G6 -> 1600
B7: NRHA Novice Horse L1 | C7: 9 | D7: =(450-E7)*0.1 -> 40 | E7: 50 | F7: 90 | G7: 180 | H7: =D7*C7 -> 360 | I7: =F7*C7 -> 810 | J7: 0 | K7: 1200 | L7: =C7*G7 -> 1620
B8: NRHA Open | C8: 9 | D8: =(650-E8)*0.1 -> 60 | E8: 50 | F8: 90 | G8: 200 | H8: =D8*C8 -> 540 | I8: =F8*C8 -> 810 | J8: 0 | K8: 4400 | L8: =C8*G8 -> 1800
B9: NRHA Prime Time Non Pro | C9: 7 | D9: =(450-E9)*0.1 -> 40 | E9: 50 | F9: =G9-E9-D9 -> 90 | G9: 180 | H9: =D9*C9 -> 280 | I9: =F9*C9 -> 630 | J9: 0 | K9: 1200 | L9: =C9*G9 -> 1260
B10: NRHA Unrestricted Youth | C10: 8 | D10: 20 | E10: 0 | F10: 0 | G10: 20 | H10: =D10*C10 -> 160 | I10: =F10*C10 -> 0 | J10: 0 | K10: 0 | L10: =C10*G10 -> 160
B11: NRHA Youth 13 & Under | C11: 5 | D11: 20 | E11: 0 | F11: 0 | G11: 20 | H11: =D11*C11 -> 100 | I11: =F11*C11 -> 0 | J11: 0 | K11: 0 | L11: =C11*G11 -> 100
B12: NRHA Youth 14-18 | C12: 6 | D12: 20 | E12: 0 | F12: 0 | G12: 20 | H12: =D12*C12 -> 120 | I12: =F12*C12 -> 0 | J12: 0 | K12: 0 | L12: =C12*G12 -> 120
B13: ריינינג ירוקי התאחדות | C13: 25 | D13: 35 | E13: 50 | F13: 100 | G13: 185 | H13: =D13*C13 -> 875 | I13: =F13*C13 -> 2500 | J13: 2500 | K13: 0 | L13: =C13*G13 -> 4625
B14: ריינינג ירוקי נוער | C14: 16 | D14: 20 | E14: 0 | F14: 0 | G14: 20 | H14: =D14*C14 -> 320 | I14: =F14*C14 -> 0 | J14: 0 | K14: 0 | L14: =C14*G14 -> 320
B15: ריינינג נוביס - התאחדות | C15: 15 | D15: 35 | E15: 50 | F15: 100 | G15: 185 | H15: =D15*C15 -> 525 | I15: =F15*C15 -> 1500 | J15: 1500 | K15: 0 | L15: =C15*G15 -> 2775
B16: ריינינג נוביס נונ פרו | C16: 9 | D16: 35 | E16: 50 | F16: 100 | G16: 185 | H16: =D16*C16 -> 315 | I16: =F16*C16 -> 900 | J16: 900 | K16: 0 | L16: =C16*G16 -> 1665
B17: ריינינג נונ פרו לבני 50+ התאחדות | C17: 10 | D17: 35 | E17: 50 | F17: 100 | G17: 185 | H17: =D17*C17 -> 350 | I17: =F17*C17 -> 1000 | J17: 1000 | K17: 0 | L17: =C17*G17 -> 1850
B18: NRHA Non Pro | C18: 17 | D18: =(650-E18)*0.1 -> 60 | E18: 50 | F18: =G18-E18-D18 -> 140 | G18: 250 | H18: =D18*C18 -> 1020 | I18: =F18*C18 -> 2380 | J18: 0 | K18: 8000 | L18: =C18*G18 -> 4250
B19: NRHA Limited Non Pro | C19: 9 | D19: =(450-E19)*0.1 -> 40 | E19: 50 | F19: =G19-E19-D19 -> 90 | G19: 180 | H19: =D19*C19 -> 360 | I19: =F19*C19 -> 810 | J19: 0 | K19: 2000 | L19: =C19*G19 -> 1620
B20: NRHA Limited Open | C20: 7 | D20: =(500-E20)*0.1 -> 45 | E20: 50 | F20: =G20-E20-D20 -> 105 | G20: 200 | H20: =D20*C20 -> 315 | I20: =F20*C20 -> 735 | J20: 0 | K20: 2000 | L20: =C20*G20 -> 1400
B21: NRHA Novice Horse L1 | C21: 10 | D21: =(550-E21)*0.1 -> 50 | E21: 50 | F21: =G21-E21-D21 -> 140 | G21: 240 | H21: =D21*C21 -> 500 | I21: =F21*C21 -> 1400 | J21: 0 | K21: 4000 | L21: =C21*G21 -> 2400 | N21: =130*50 -> 6500
B22: NRHA Open | C22: 9 | D22: =(650-E22)*0.1 -> 60 | E22: 50 | F22: =G22-E22-D22 -> 140 | G22: 250 | H22: =D22*C22 -> 540 | I22: =F22*C22 -> 1260 | J22: 0 | K22: 8400 | L22: =C22*G22 -> 2250
B23: NRHA Prime Time Non Pro | C23: 6 | D23: =(550-E23)*0.1 -> 50 | E23: 50 | F23: =G23-E23-D23 -> 140 | G23: 240 | H23: =D23*C23 -> 300 | I23: =F23*C23 -> 840 | J23: 0 | K23: 4000 | L23: =C23*G23 -> 1440
B24: NRHA Unrestricted Youth | C24: 0 | D24: 20 | E24: 0 | F24: 0 | G24: 20 | H24: =D24*C24 -> 0 | I24: =F24*C24 -> 0 | J24: 0 | K24: 0 | L24: =C24*G24 -> 0
B25: NRHA Youth 13 & Under | C25: 4 | D25: 20 | E25: 0 | F25: 0 | G25: 20 | H25: =D25*C25 -> 80 | I25: =F25*C25 -> 0 | J25: 0 | K25: 0 | L25: =C25*G25 -> 80
B26: NRHA Youth 14-18 | C26: 3 | D26: 20 | E26: 0 | F26: 0 | G26: 20 | H26: =D26*C26 -> 60 | I26: =F26*C26 -> 0 | J26: 0 | K26: 0 | L26: =C26*G26 -> 60
B27: ריינינג ירוקי התאחדות | C27: 26 | D27: =(500-E27)*0.1 -> 45 | E27: 50 | F27: =G27-E27-D27 -> 100 | G27: 195 | H27: =D27*C27 -> 1170 | I27: =F27*C27 -> 2600 | J27: 2600 | K27: 2000 | L27: =C27*G27 -> 5070
B28: ריינינג ירוקי נוער | C28: 18 | D28: 20 | E28: 0 | F28: 0 | G28: 20 | H28: =D28*C28 -> 360 | I28: =F28*C28 -> 0 | J28: 0 | K28: 0 | L28: =C28*G28 -> 360
B29: ריינינג נוביס - התאחדות | C29: 9 | D29: =(500-E29)*0.1 -> 45 | E29: 50 | F29: =G29-E29-D29 -> 100 | G29: 195 | H29: =D29*C29 -> 405 | I29: =F29*C29 -> 900 | J29: 900 | K29: 2000 | L29: =C29*G29 -> 1755
B30: ריינינג נוביס נונ פרו | C30: 7 | D30: =(500-E30)*0.1 -> 45 | E30: 50 | F30: =G30-E30-D30 -> 100 | G30: 195 | H30: =D30*C30 -> 315 | I30: =F30*C30 -> 700 | J30: 700 | K30: 2000 | L30: =C30*G30 -> 1365
B31: ריינינג נונ פרו לבני 50+ התאחדות | C31: 5 | D31: =(500-E31)*0.1 -> 45 | E31: 50 | F31: =G31-E31-D31 -> 100 | G31: 195 | H31: =D31*C31 -> 225 | I31: =F31*C31 -> 500 | J31: 500 | K31: 2000 | L31: =C31*G31 -> 975
H32: =SUM(H4:H31) -> 11335 | I32: =SUM(I4:I31) -> 24285 | J32: =SUM(J4:J31) -> 10600 | K32: =SUM(K4:K31) -> 50400 | L32: =SUM(L4:L31) -> 46870
B35: סה"כ קבלות התאחדות מהלוגליג | C35: =[1]קבלות!O103+[1]קבלות!P103-[1]קבלות!O101 -> 45275
B36: בוצעה העברה להתאחדות מליאור דובובסקי לא נמצא בלוגליג | C36: =[1]קבלות!O101 -> 2310
B37: זיכויים | C37: =- ([1]קבלות!P92+[1]קבלות!P79+[1]קבלות!P51+[1]קבלות!P33) -> -715
B38: סה"כ גביה ממתחרים | C38: =C35+C36+C37 -> 46870
B40: כמות כניסות לקופון דרבי | C40: =C4+C5 +C6+C8+C9+C10+C11+C14+C15+C16+C19+C20+C21+C22+C24+C27+C28+C29+C30+C31 -> 205
B41: סה"כ קופון דרבי (50 ₪) | C41: =C40*50 -> 10250
B42: סה"כ קופון ענף | C42: =H32 -> 11335
B43: סה"כ גביה ממתחרים לפרס | C43: =I32 -> 24285
...

Sheet 5+6
A1: תחרות בוגרים 5+6 - 2024
B2: מספר כניסות | C2: חווה | D2: התאחדות | E2: סה"כ | F2: סה"כ תוכנה | G2: סה"כ חווה | H2: סה"כ התאחדות
A3: פייד טיים שני | B3: 14 | C3: 170 | D3: 0 | E3: =C3+D3 -> 170 | F3: =E3*B3 -> 2380 | G3: =C3*B3 -> 2380 | H3: =D3*B3 -> 0
A4: פייד טיים שני כפול | B4: 63 | C4: 240 | D4: 0 | E4: =C4+D4 -> 240 | F4: =E4*B4 -> 15120 | G4: =C4*B4 -> 15120 | H4: =D4*B4 -> 0
A5: פייד טיים שלישי בוקר | B5: 3 | C5: 170 | D5: 0 | E5: =C5+D5 -> 170 | F5: =E5*B5 -> 510 | G5: =C5*B5 -> 510 | H5: =D5*B5 -> 0
A6: פייד טיים שלישי בוקר כפול | B6: 13 | C6: 240 | D6: 0 | E6: =C6+D6 -> 240 | F6: =E6*B6 -> 3120 | G6: =C6*B6 -> 3120 | H6: =D6*B6 -> 0
A7: פייד טיים שלישי קבוצתי | B7: 14 | C7: 100 | D7: 0 | E7: =C7+D7 -> 100 | F7: =E7*B7 -> 1400 | G7: =C7*B7 -> 1400 | H7: =D7*B7 -> 0
A8: ריינינג פתוח לא מוגבל | B8: 15 | C8: 250 | D8: 0 | E8: =C8+D8 -> 250 | F8: =E8*B8 -> 3750 | G8: =C8*B8 -> 3750 | H8: =D8*B8 -> 0
A9: NRHA Unrestricted Youth | B9: 2 | C9: 180 | D9: 20 | E9: =C9+D9 -> 200 | F9: =E9*B9 -> 400 | G9: =C9*B9 -> 360 | H9: =D9*B9 -> 40
A10: ריינינג נוביס נונ פרו | B10: 6 | C10: 305 | D10: 195 | E10: =C10+D10 -> 500 | F10: =E10*B10 -> 3000 | G10: =C10*B10 -> 1830 | H10: =D10*B10 -> 1170
A11: NRHA Youth 14-18 | B11: 6 | C11: 180 | D11: 20 | E11: =C11+D11 -> 200 | F11: =E11*B11 -> 1200 | G11: =C11*B11 -> 1080 | H11: =D11*B11 -> 120
A12: NRHA Youth 13 & Under | B12: 4 | C12: 180 | D12: 20 | E12: =C12+D12 -> 200 | F12: =E12*B12 -> 800 | G12: =C12*B12 -> 720 | H12: =D12*B12 -> 80
A13: ריינינג נוביס - התאחדות | B13: 5 | C13: 305 | D13: 195 | E13: =C13+D13 -> 500 | F13: =E13*B13 -> 2500 | G13: =C13*B13 -> 1525 | H13: =D13*B13 -> 975
A14: מטוריטי נונ פרו NRHA | B14: 8 | C14: 440 | D14: 160 | E14: =C14+D14 -> 600 | F14: =E14*B14 -> 4800 | G14: =C14*B14 -> 3520 | H14: =D14*B14 -> 1280
... A67: מקצה לרישום דמי ביטול ושינוי לפני תחרות | B67: 33 | C67: 50 | D67: 0 | E67: =C67+D67 -> 50 | F67: =E67*B67 -> 1650 | G67: =C67*B67 -> 1650 | H67: =D67*B67 -> 0
B68: =SUM(B3:B67) -> 518 | F68: =SUM(F3:F67) -> 230870 | G68: =SUM(G3:G67) -> 166330 | H68: =SUM(H3:H67) -> 64540
A70: רישום מאוחר | B70: 22 | C70: 50 | D70: 0 | E70: =C70+D70 -> 50 | F70: =B70*C70 -> 1100 | G70: =F70 -> 1100 | H70: =D70*B70 -> 0
A71: תאים | B71: 1 | C71: 90197.5 | D71: 0 | E71: =C71+D71 -> 90197.5 | F71: =B71*C71 -> 90197.5 | G71: =F71 -> 90197.5 | H71: =D71*B71 -> 0
A72: נסורת | B72: =[2]קבלות!H128+[2]קופה!I54 -> 556 | C72: 30 | D72: 0 | E72: =C72+D72 -> 30 | F72: =B72*C72 -> 16680 | G72: =F72 -> 16680 | H72: =D72*B72 -> 0
C73: 20 | D73: 0 | E73: =C73+D73 -> 20 | F73: =B73*C73 -> 0 | G73: =F73 -> 0 | H73: =D73*B73 -> 0
G74: =SUM(G70:G73) -> 107977.5 | H74: =SUM(H70:H73) -> 0
A75: סה"כ כניסות | B75: =SUM(B8:B17)+SUM(B24:B32)+SUM(B39:B47)+SUM(B54:B66) -> 333
A76: סה"כ פייד טיים | B76: =SUM(B3:B7)+SUM(B18:B23)+SUM(B33:B38)+SUM(B48:B53) -> 152 | E76: סה"כ הכנסות | G76: =G68+G74 -> 274307.5 | H76: =H68+H74 -> 64540
A77: סה"כ הכנסות מכניסות | B77: =SUM(G8:G17)+SUM(G24:G32)+SUM(G39:G47)+SUM(G54:G66) -> 131560
A78: סה"כ הכנסות מפייד טיים | B78: =SUM(G3:G7)+SUM(G18:G23)+SUM(G33:G38)+SUM(G48:G53) -> 33120

Sheet 7+8
A1: תחרות בוגרים 7+8 - 2024
B2: מספר כניסות | C2: חווה | D2: התאחדות | E2: סה"כ | F2: סה"כ תוכנה | G2: סה"כ חווה | H2: סה"כ התאחדות
A3: פייד טיים שלישי | B3: 26 | C3: 170 | D3: 0 | E3: =C3+D3 -> 170 | F3: =E3*B3 -> 4420 | G3: =C3*B3 -> 4420 | H3: =D3*B3 -> 0
A4: פייד טיים שלישי כפול | B4: 60 | C4: 240 | D4: 0 | E4: =C4+D4 -> 240 | F4: =E4*B4 -> 14400 | G4: =C4*B4 -> 14400 | H4: =D4*B4 -> 0
A5: פייד טיים רביעי בוקר | B5: 1 | C5: 170 | D5: 0 | E5: =C5+D5 -> 170 | F5: =E5*B5 -> 170 | G5: =C5*B5 -> 170 | H5: =D5*B5 -> 0
A6: פייד טיים רביעי בוקר כפול | B6: 1 | C6: 240 | D6: 0 | E6: =C6+D6 -> 240 | F6: =E6*B6 -> 240 | G6: =C6*B6 -> 240 | H6: =D6*B6 -> 0 | L6: =250*4+2000*4+1000*4+1250*4 -> 18000
A7: ריינינג פתוח לא מוגבל | B7: 17 | C7: =E7-D7 -> 250 | D7: 0 | E7: 250 | F7: =E7*B7 -> 4250 | G7: =C7*B7 -> 4250 | H7: =D7*B7 -> 0
A8: נוער UNRESTRICTED NRHA | B8: 2 | C8: =E8-D8 -> 181 | D8: 19 | E8: 200 | F8: =E8*B8 -> 400 | G8: =C8*B8 -> 362 | H8: =D8*B8 -> 38
A9: נוביס נונ פרו התאחדות | B9: 5 | C9: =E9-D9 -> 227 | D9: 173 | E9: 400 | F9: =E9*B9 -> 2000 | G9: =C9*B9 -> 1135 | H9: =D9*B9 -> 865
A10: נוער 14-18 NRHA | B10: 3 | C10: =E10-D10 -> 181 | D10: 19 | E10: 200 | F10: =E10*B10 -> 600 | G10: =C10*B10 -> 543 | H10: =D10*B10 -> 57
A11: נוער 13 NRHA | B11: 7 | C11: =E11-D11 -> 181 | D11: 19 | E11: 200 | F11: =E11*B11 -> 1400 | G11: =C11*B11 -> 1267 | H11: =D11*B11 -> 133 | L11: 2023
A12: נוביס התאחדות | B12: 19 | C12: =E12-D12 -> 227 | D12: 173 | E12: 400 | F12: =E12*B12 -> 7600 | G12: =C12*B12 -> 4313 | H12: =D12*B12 -> 3287 | J12: 40 | K12: 29 | L12: קאטינג
A13: נונ פרו NRHA | B13: 12 | C13: =E13-D13 -> 276 | D13: 224 | E13: 500 | F13: =E13*B13 -> 6000 | G13: =C13*B13 -> 3312 | H13: =D13*B13 -> 2688 | J13: 193 | K13: 147 | L13: ריינינג
A14: נונ פרו מוגבל NRHA | B14: 5 | C14: =E14-D14 -> 283 | D14: 167 | E14: 450 | F14: =E14*B14 -> 2250 | G14: =C14*B14 -> 1415 | H14: =D14*B14 -> 835 | K14: =SUM(K12:K13) -> 176
A15: נונ פרו פריים טיים 40+ NRHA | B15: 8 | C15: =E15-D15 -> 283 | D15: 167 | E15: 450 | F15: =E15*B15 -> 3600 | G15: =C15*B15 -> 2264 | H15: =D15*B15 -> 1336 | L15: 2024
A16: פטוריטי נונ פרו לבני 3 IRBC | B16: 5 | C16: =E16-D16 -> 251 | D16: 149 | E16: 400 | F16: =E16*B16 -> 2000 | G16: =C16*B16 -> 1255 | H16: =D16*B16 -> 745 | K16: 29 | L16: קאטינג
A17: פייד טיים רביעי ערב | B17: 3 | C17: 170 | D17: 0 | E17: =C17+D17 -> 170 | F17: =E17*B17 -> 510 | G17: =C17*B17 -> 510 | H17: =D17*B17 -> 0 | J17: 177 | K17: 116 | L17: ריינינג
A18: פייד טיים רביעי ערב כפול | B18: 26 | C18: 240 | D18: 0 | E18: =C18+D18 -> 240 | F18: =E18*B18 -> 6240 | G18: =C18*B18 -> 6240 | H18: =D18*B18 -> 0 | K18: =SUM(K16:K17) -> 145
A19: פייד טיים חמישי בוקר כפול | B19: 4 | C19: 240 | D19: 0 | E19: =C19+D19 -> 240 | F19: =E19*B19 -> 960 | G19: =C19*B19 -> 960 | H19: =D19*B19 -> 0
A20: פייד טיים חמישי בוקר | B20: 0 | C20: 170 | D20: 0 | E20: =C20+D20 -> 170 | F20: =E20*B20 -> 0 | G20: =C20*B20 -> 0 | H20: =D20*B20 -> 0
A21: פתוח לא מוגבל | B21: 14 | C21: =E21-D21 -> 250 | D21: 0 | E21: 250 | F21: =E21*B21 -> 3500 | G21: =C21*B21 -> 3500 | H21: =D21*B21 -> 0
A22: ירוקי נוער התאחדות | B22: 17 | C22: =E22-D22 -> 181 | D22: 19 | E22: 200 | F22: =E22*B22 -> 3400 | G22: =C22*B22 -> 3077 | H22: =D22*B22 -> 323
A23: ירוקי התאחדות | B23: 22 | C23: =E23-D23 -> 227 | D23: 173 | E23: 400 | F23: =E23*B23 -> 8800 | G23: =C23*B23 -> 4994 | H23: =D23*B23 -> 3806
A24: דרבי נונ פרו L4 | B24: 18 | C24: =E24-D24 -> 1176 | D24: 424 | E24: 1600 | F24: =E24*B24 -> 28800 | G24: =C24*B24 -> 21168 | H24: =D24*B24 -> 7632
A25: דרבי נונ פרו L1 | B25: 11 | C25: =E25-D25 -> 517 | D25: 133 | E25: 650 | F25: =E25*B25 -> 7150 | G25: =C25*B25 -> 5687 | H25: =D25*B25 -> 1463
A26: דרבי נונ פרו L2 | B26: 16 | C26: =E26-D26 -> 842 | D26: 158 | E26: 1000 | F26: =E26*B26 -> 16000 | G26: =C26*B26 -> 13472 | H26: =D26*B26 -> 2528
A27: נונ פרו NRHA | B27: 17 | C27: =E27-D27 -> 279 | D27: 371 | E27: 650 | F27: =E27*B27 -> 11050 | G27: =C27*B27 -> 4743 | H27: =D27*B27 -> 6307
A28: נונ פרו מוגבל NRHA | B28: 6 | C28: =E28-D28 -> 226 | D28: 224 | E28: 450 | F28: =E28*B28 -> 2700 | G28: =C28*B28 -> 1356 | H28: =D28*B28 -> 1344
A29: נונ פרו פריים טיים 40+ NRHA | B29: 8 | C29: =E29-D29 -> 276 | D29: 224 | E29: 500 | F29: =E29*B29 -> 4000 | G29: =C29*B29 -> 2208 | H29: =D29*B29 -> 1792
A30: דרבי נונ פרו פריים טיים | B30: 6 | C30: =E30-D30 -> 842 | D30: 158 | E30: 1000 | F30: =E30*B30 -> 6000 | G30: =C30*B30 -> 5052 | H30: =D30*B30 -> 948
A31: פייד טיים חמישי ערב | B31: 0 | C31: 170 | D31: 0 | E31: 170 | F31: =E31*B31 -> 0 | G31: =C31*B31 -> 0 | H31: =D31*B31 -> 0
A32: פייד טיים חמישי ערב כפול | B32: 20 | C32: 240 | D32: 0 | E32: 240 | F32: =E32*B32 -> 4800 | G32: =C32*B32 -> 4800 | H32: =D32*B32 -> 0
A33: פייד טיים שישי בוקר כפול | B33: 3 | C33: 240 | D33: 0 | E33: 240 | F33: =E33*B33 -> 720 | G33: =C33*B33 -> 720 | H33: =D33*B33 -> 0
A34: פייד טיים שישי בוקר | B34: 2 | C34: 170 | D34: 0 | E34: 170 | F34: =E34*B34 -> 340 | G34: =C34*B34 -> 340 | H34: =D34*B34 -> 0
A35: פתוח לא מוגבל | B35: 12 | C35: =E35-D35 -> 250 | D35: 0 | E35: 250 | F35: =E35*B35 -> 3000 | G35: =C35*B35 -> 3000 | H35: =D35*B35 -> 0
A36: נוער UNRESTRICTED NRHA | B36: 1 | C36: =E36-D36 -> 181 | D36: 19 | E36: 200 | F36: =E36*B36 -> 200 | G36: =C36*B36 -> 181 | H36: =D36*B36 -> 19
A37: נוער 14-18 NRHA | B37: 5 | C37: =E37-D37 -> 181 | D37: 19 | E37: 200 | F37: =E37*B37 -> 1000 | G37: =C37*B37 -> 905 | H37: =D37*B37 -> 95
A38: נוער 13 NRHA | B38: 6 | C38: =E38-D38 -> 181 | D38: 19 | E38: 200 | F38: =E38*B38 -> 1200 | G38: =C38*B38 -> 1086 | H38: =D38*B38 -> 114
A39: נונ פרו 50+ | B39: 7 | C39: =E39-D39 -> 227 | D39: 173 | E39: 400 | F39: =E39*B39 -> 2800 | G39: =C39*B39 -> 1589 | H39: =D39*B39 -> 1211
A40: פתוח NRHA | B40: 5 | C40: =E40-D40 -> 209 | D40: 291 | E40: 500 | F40: =E40*B40 -> 2500 | G40: =C40*B40 -> 1045 | H40: =D40*B40 -> 1455
...

Sheet 9+10
A1: תחרות בוגרים 9+10 - 2024
B2: מספר כניסות | C2: חווה | D2: התאחדות | E2: סה"כ | F2: סה"כ תוכנה | G2: סה"כ חווה | H2: סה"כ התאחדות
A3: פייד טיים שלישי | B3: 15 | C3: 170 | D3: 0 | E3: =C3+D3 -> 170 | F3: =E3*B3 -> 2550 | G3: =C3*B3 -> 2550 | H3: =D3*B3 -> 0
A4: פייד טיים שלישי כפול | B4: 73 | C4: 240 | D4: 0 | E4: =C4+D4 -> 240 | F4: =E4*B4 -> 17520 | G4: =C4*B4 -> 17520 | H4: =D4*B4 -> 0
A5: פייד טיים רביעי בוקר | B5: 2 | C5: 170 | D5: 0 | E5: =C5+D5 -> 170 | F5: =E5*B5 -> 340 | G5: =C5*B5 -> 340 | H5: =D5*B5 -> 0
A6: פייד טיים רביעי בוקר כפול | B6: 5 | C6: 240 | D6: 0 | E6: =C6+D6 -> 240 | F6: =E6*B6 -> 1200 | G6: =C6*B6 -> 1200 | H6: =D6*B6 -> 0
A7: ריינינג פתוח לא מוגבל | B7: 14 | C7: 250 | D7: 0 | E7: =C7+D7 -> 250 | F7: =E7*B7 -> 3500 | G7: =C7*B7 -> 3500 | H7: =D7*B7 -> 0
A8: נונ פרו NRHA | B8: 12 | C8: 250 | D8: 250 | E8: =C8+D8 -> 500 | F8: =E8*B8 -> 6000 | G8: =C8*B8 -> 3000 | H8: =D8*B8 -> 3000
A9: נונ פרו מוגבל NRHA | B9: 5 | C9: 200 | D9: 200 | E9: =C9+D9 -> 400 | F9: =E9*B9 -> 2000 | G9: =C9*B9 -> 1000 | H9: =D9*B9 -> 1000
A10: נונ פרו פריים טיים 40+ NRHA | B10: 7 | C10: 200 | D10: 200 | E10: =C10+D10 -> 400 | F10: =E10*B10 -> 2800 | G10: =C10*B10 -> 1400 | H10: =D10*B10 -> 1400
A11: נוער 14-18 NRHA | B11: 3 | C11: 180 | D11: 20 | E11: =C11+D11 -> 200 | F11: =E11*B11 -> 600 | G11: =C11*B11 -> 540 | H11: =D11*B11 -> 60
A12: נוער 13 NRHA | B12: 6 | C12: 180 | D12: 20 | E12: =C12+D12 -> 200 | F12: =E12*B12 -> 1200 | G12: =C12*B12 -> 1080 | H12: =D12*B12 -> 120
A13: נוביס התאחדות | B13: 11 | C13: 205 | D13: 195 | E13: =C13+D13 -> 400 | F13: =E13*B13 -> 4400 | G13: =C13*B13 -> 2255 | H13: =D13*B13 -> 2145
A14: נוביס נונ פרו התאחדות | B14: 12 | C14: 205 | D14: 195 | E14: =C14+D14 -> 400 | F14: =E14*B14 -> 4800 | G14: =C14*B14 -> 2460 | H14: =D14*B14 -> 2340
... A58: מקצה לרישום דמי ביטול ושינוי לפני תחרות | B58: 11 | C58: 50 | D58: 0 | E58: =C58+D58 -> 50 | F58: =E58*B58 -> 550 | G58: =C58*B58 -> 550 | H58: =D58*B58 -> 0
B59: =SUM(B3:B58) -> 515 | F59: =SUM(F3:F58) -> 215800 | G59: =SUM(G3:G58) -> 148885 | H59: =SUM(H3:H58) -> 66915
A61: רישום מאוחר | B61: 24 | C61: 50 | D61: 0 | E61: =C61+D61 -> 50 | F61: =B61*C61 -> 1200 | G61: =F61 -> 1200 | H61: =D61*B61 -> 0
A62: תאים | B62: 1 | C62: 83450 | D62: 0 | E62: =C62+D62 -> 83450 | F62: =B62*C62 -> 83450 | G62: =F62 -> 83450 | H62: =D62*B62 -> 0
A63: נסורת | B63: =[3]קבלות!I182 -> 287 | C63: 35 | D63: 0 | E63: =C63+D63 -> 35 | F63: =B63*C63 -> 10045 | G63: =F63 -> 10045 | H63: =D63*B63 -> 0
A64: כרטיסים | B64: =[3]קבלות!J182 -> 138 | C64: 50 | D64: 0 | E64: =C64+D64 -> 50 | F64: =B64*C64 -> 6900 | G64: =F64 -> 6900 | H64: =D64*B64 -> 0
G65: =SUM(G61:G64) -> 101595 | H65: =SUM(H61:H64) -> 0
A67: סה"כ הכנסות ממקצים | B67: =SUM(G7:G14)+SUM(G19:G28)+SUM(G33:G44)+SUM(G49:G57) -> 110685 | E67: סה"כ הכנסות | G67: =G59+G65 -> 250480 | H67: =H59+H65 -> 66915
A68: סה"כ הכנסות מפייד טיים | B68: =SUM(G3:G6)+SUM(G15:G18)+SUM(G29:G32)+SUM(G45:G48) -> 37650
A69: כמות כניסות | B69: 307
A70: כמות פייד טיימים | B70: 163

Sheet סיכום
C3: גרין פילדס | D3: דאבל קיי | E3: דאבל קיי | F3: גרין פילדס | G3: גרין פילדס
B4: 2024 | C4: 1+2 | D4: 3+4 | E4: 5+6 B2W | F4: 7+8 IRBC דרבי | G4: 9+10 אליפות ופטוריטי
B5: הכנסות מקצים | C5: 94032 | D5: 84930 | E5: 131560 | F5: 165109 | G5: 110685
B6: הכנסות פייד טיים | D6: 26280 | E6: 33120 | F6: 36330 | G6: 37650
B7: הכנסות תאים | D7: 78010 | E7: 90197.5 | F7: 83450 | G7: 83450
B8: הכנסות נסורת | D8: 13620 | E8: 16680 | F8: 10045 | G8: 10045
B9: הכנסות מקהל | D9: 0 | E9: 0 | F9: =G9*2 -> 13800 | G9: 6900
C10: =SUM(C5:C9) -> 94032 | D10: =SUM(D5:D9) -> 202840 | E10: =SUM(E5:E9) -> 271557.5 | F10: =SUM(F5:F9) -> 308734 | G10: =SUM(G5:G9) -> 248730
C12: גרין פילדס | D12: דאבל קיי | E12: דאבל קיי | F12: גרין פילדס | G12: גרין פילדס
B13: 2024 | C13: 1+2 IRBC 2023 | D13: 3+4 | E13: 5+6 B2W | F13: 7+8 דרבי | G13: 9+10 אליפות ופטוריטי | H13: סה"כ
B14: כסף שיצא בצ'קים | C14: =21550+188980.745 -> 210530.74 | D14: 78090 | E14: 164215 | F14: =188597.25+12900 -> 201497.25 | G14: 244185 | H14: =SUM(C14:G14) -> 898517.99
B15: כסף שניתן במקצי שיא | C15: =64936.11+90200.13 -> 155136.24 | D15: 0 | E15: 82000 | F15: 105948 | G15: 133240 | H15: =SUM(C15:G15) -> 476324.24
B16: כסף שנתן המארגן מקצי שיא | C16: 33000 | D16: 0 | E16: 82000 | F16: 30000 | G16: 40000 | H16: =SUM(C16:G16) -> 185000
B17: כסף שנתן המארגן מקצי ליגה | C17: 35900 | D17: 14000 | E17: =108996-82000 -> 26996 | F17: 36000 | G17: =36000+2901 -> 38901 | H17: =SUM(C17:G17) -> 151797
C21: גרין פילדס | D21: גרין פילדס | E21: גרין פילדס | F21: דאבל קיי | G21: בוטלה
B22: 2023 | C22: 1+2 | D22: 3+4 | E22: 5+6 ודרבי IRBC | F22: 7+8 | G22: 9+10 | H22: סה"כ
B23: כסף שיצא בצ'קים | C23: =15700+25260 -> 40960 | D23: =11500+25046 -> 36546 | E23: =26999.8+200643.05 -> 227642.85 | F23: =15700+22892 -> 38592 | H23: =SUM(C23:G23) -> 343740.85
B24: כסף שניתן במקצי שיא | E24: =52948.71+25895.7+1596+11118.8+800+5985+28564.7+68531.72+200 -> 195640.63 | H24: =SUM(C24:G24) -> 195640.63
C27: גרין פילדס | D27: דאבל קיי | E27: דאבל קיי | F27: דאבל קיי | G27: גרין פילדס | H27: גרין פילדס
B28: 2022 | C28: 1+2 | D28: 3+4 | E28: 5+6 ודרבי | F28: 7+8 | G28: 9+10 ופטוריטי התאחדות | H28: אליפות ופטוריטי IRBC | I28: סה"כ
B29: כסף שיצא בצ'קים | C29: =8800+13530.4 -> 22330.4 | D29: =9000+16940 -> 25940 | E29: =8300+87833.14 -> 96133.14 | F29: =8700+27035 -> 35735 | G29: =10000+28676 -> 38676 | H29: =4100+19996.53 -> 24096.53 | I29: =SUM(C29:H29) -> 242911.07
B30: כסף שניתן במקצי שיא | E30: =15977+8638+35660+10035.14 -> 70310.14 | G30: =3090+6994 -> 10084 | H30: =39208.67+64818.86 -> 104027.53 | I30: =SUM(C30:H30) -> 184421.67
C32: גרין פילדס\דאבל קיי | D32: דאבל קיי/ גרין פילדס | E32: גרין פילדס | F32: גרין פילדס | G32: דאבל קיי
B33: IRBC | C33: 2021 | D33: 2022 | E33: 2023 | F33: 2024 | G33: 2025
B34: דרבי פתוח | C34: =12585+7460+58306 -> 78351 | D34: =35660+10035.14 -> 45695.14 | E34: =5985+28564.7+68531.72 -> 103081.42 | F34: =36155.71+14426.7+8784.7 -> 59367.11 | G34: =798+32206.89+52265.88 -> 85270.77 | H34: התאחדות ולא IRBC
B35: דרבי נונ פרו | C35: =12309+38347+9900 -> 60556 | D35: =8638+15977 -> 24615 | E35: =11118.8+1596+25895.7+52948.71 -> 91559.21 | F35: =8784.71+5463.01+34124.71+14974.7 -> 63347.13 | G35: =399+1596+43211.84+24812.9 -> 70019.74
B36: פטוריטי פתוח | C36: 43392.32 | D36: 64818.86 | E36: 90200.13 | F36: =70829.8+9040 -> 79869.8
B37: פטוריטי נונ פרו | C37: 23975 | D37: 39208.67 | E37: 64936.11 | F37: =60231.64+10781.68 -> 71013.32
B38: סה"כ דרבי | C38: =C34+C35 -> 138907 | D38: =D34+D35 -> 70310.14 | E38: =E34+E35 -> 194640.63 | F38: =F34+F35 -> 122714.24 | G38: =G34+G35 -> 155290.51
B39: סה"כ פטוריטי | C39: =C36+C37 -> 67367.32 | D39: =D36+D37 -> 104027.53 | E39: =E36+E37 -> 155136.24 | F39: =F36+F37 -> 150883.12 | G39: =G36+G37 -> 0
B40: סה"כ IRBC | C40: =SUM(C36:C37) -> 67367.32 | D40: =SUM(D36:D37) -> 104027.53 | E40: =SUM(E34:E37) -> 349776.87 | F40: =SUM(F34:F37) -> 273597.36 | G40: =SUM(G34:G37) -> 155290.51
B42: עלות כניסה 2022
B43: עלות כניסה 2023
B44: עלות כניסה 2024
